#VRML_SIM R2025a utf8

EXTERNPROTO "https://raw.githubusercontent.com/cyberbotics/webots/R2025a/projects/objects/backgrounds/protos/TexturedBackground.proto"
EXTERNPROTO "https://raw.githubusercontent.com/cyberbotics/webots/R2025a/projects/objects/backgrounds/protos/TexturedBackgroundLight.proto"
EXTERNPROTO "https://raw.githubusercontent.com/cyberbotics/webots/R2025a/projects/objects/floors/protos/Floor.proto"
EXTERNPROTO "https://raw.githubusercontent.com/cyberbotics/webots/R2025a/projects/appearances/protos/CementTiles.proto"
EXTERNPROTO "https://raw.githubusercontent.com/cyberbotics/webots/R2025a/projects/objects/living_room_furniture/protos/Carpet.proto"
EXTERNPROTO "https://raw.githubusercontent.com/cyberbotics/webots/R2025a/projects/appearances/protos/Rubber.proto"
EXTERNPROTO "https://raw.githubusercontent.com/cyberbotics/webots/R2025a/projects/objects/tables/protos/Desk.proto"
EXTERNPROTO "https://raw.githubusercontent.com/cyberbotics/webots/R2025a/projects/objects/chairs/protos/OfficeChair.proto"
EXTERNPROTO "https://raw.githubusercontent.com/cyberbotics/webots/R2025a/projects/objects/cabinet/protos/Cabinet.proto"
EXTERNPROTO "https://raw.githubusercontent.com/cyberbotics/webots/R2025a/projects/objects/plants/protos/PottedTree.proto"
EXTERNPROTO "https://raw.githubusercontent.com/cyberbotics/webots/R2025a/projects/objects/living_room_furniture/protos/Armchair.proto"
EXTERNPROTO "https://raw.githubusercontent.com/cyberbotics/webots/R2025a/projects/objects/apartment_structure/protos/Wall.proto"
EXTERNPROTO "https://raw.githubusercontent.com/cyberbotics/webots/R2025a/projects/objects/balls/protos/RobocupSoccerBall.proto"
EXTERNPROTO "https://raw.githubusercontent.com/cyberbotics/webots/R2025a/projects/objects/toys/protos/RubberDuck.proto"
EXTERNPROTO "https://raw.githubusercontent.com/cyberbotics/webots/R2025a/projects/objects/apartment_structure/protos/WallPlug.proto"
EXTERNPROTO "https://raw.githubusercontent.com/cyberbotics/webots/R2025a/projects/objects/computers/protos/DesktopComputer.proto"
EXTERNPROTO "https://raw.githubusercontent.com/cyberbotics/webots/R2025a/projects/objects/lights/protos/FloorLight.proto"
EXTERNPROTO "https://raw.githubusercontent.com/cyberbotics/webots/R2025a/projects/objects/traffic/protos/TrafficCone.proto"

WorldInfo {
  basicTimeStep 16
}
Viewpoint {
  orientation 0.2559137287163781 0.1644634216152424 -0.9526069212456346 2.1097020593361333
  position 3.319160801291539 6.089119613239038 4.719095072584563
}
TexturedBackground {
}
TexturedBackgroundLight {
}
Floor {
  size 4 4
  appearance CementTiles {
  }
}
Carpet {
  translation 0.81 1.11 -0.01
  rotation 0 0 1 3.14159
}
Robot {
  translation -1.38 0 0.066
  children [
    Gyro {
      translation -0.03 0 0
      name "gyro"
    }
    Accelerometer {
      translation -0.03 0 0
      name "accelerometer"
    }
    Lidar {
      translation -0.04 0 0.06
      name "lidar"
      children [
        Shape {
          appearance PBRAppearance {
            baseColor 0 0 0
            roughness 1
            metalness 0
          }
          geometry Box {
            size 0.1 0.1 0.08
          }
        }
      ]
    }
    DEF BODY Shape {
      appearance PBRAppearance {
        baseColorMap ImageTexture {
          url [
            "uvmap.png"
          ]
        }
        roughness 1
        metalness 0
      }
      geometry Mesh {
        url [
          "tqbot_mesh.obj"
        ]
      }
    }
    HingeJoint {
      jointParameters HingeJointParameters {
        axis 0 1 0
        anchor 0.06 0.1 -0.022
      }
      device [
        RotationalMotor {
          name "wheel_front_left"
          maxVelocity 100
        }
      ]
      endPoint Solid {
        translation 0.06 0.1 -0.022
        rotation 1 0 0 1.5708
        children [
          DEF WHEEL Shape {
            appearance Rubber {
            }
            geometry Cylinder {
              height 0.03
              radius 0.04
              subdivision 24
            }
          }
        ]
        name "wheel_front_left"
        boundingObject USE WHEEL
        physics Physics {
        }
      }
    }
    HingeJoint {
      jointParameters HingeJointParameters {
        axis 0 1 0
        anchor 0.06 -0.1 -0.022
      }
      device [
        RotationalMotor {
          name "wheel_front_right"
          maxVelocity 100
        }
      ]
      endPoint Solid {
        translation 0.06 -0.1 -0.022
        rotation 1 0 0 1.5708
        children [
          USE WHEEL
        ]
        name "wheel_front_right"
        boundingObject USE WHEEL
        physics Physics {
        }
      }
    }
    BallJoint {
      jointParameters BallJointParameters {
        anchor -0.17 0 -0.033
      }
      endPoint Solid {
        translation -0.17 0 -0.033
        children [
          DEF BALL Shape {
            appearance Rubber {
            }
            geometry Sphere {
              radius 0.03
              subdivision 3
            }
          }
        ]
        name "wheel_back"
        boundingObject USE BALL
        physics Physics {
        }
      }
    }
    Camera {
      translation 0.13 -0.09 0.02
      children [
        Shape {
          appearance PBRAppearance {
            baseColor 0 0 0
            roughness 1
            metalness 0
          }
          geometry Box {
            size 0.03 0.03 0.03
          }
        }
      ]
      name "cam_right"
    }
    DistanceSensor {
      translation 0.13 0.09 0.02
      rotation 0 0 -1 -0.038205307179586256
      children [
        Shape {
          appearance PBRAppearance {
            baseColor 0 0 0
            roughness 1
            metalness 0
          }
          geometry Box {
            size 0.03 0.03 0.03
          }
        }
      ]
      name "ds_left"
    }
  ]
  name "tqbot"
  boundingObject USE BODY
  physics Physics {
    density -1
    mass 1
  }
  controller "<extern>"
}
Desk {
  translation 1.65 -1.32 0
}
OfficeChair {
  translation 1.03 -1.29 0
}
Cabinet {
  translation 1.98 -0.169999 0
  rotation 0 0 1 -3.1415853071795863
}
PottedTree {
  translation -1.73 1.69 0
}
Armchair {
  translation -1.02999 -1.38 0
  rotation 0 0 1 1.5708
}
Wall {
  translation 2.03 0 0
  size 0.1 4 0.9
}
Wall {
  translation -2.03 0 0
  name "wall(1)"
  size 0.1 4 0.9
}
Wall {
  translation 0.0099931 1.95001 0
  rotation 0 0 1 1.5708
  name "wall(2)"
  size 0.1 4 0.9
}
Wall {
  translation 0.0100072 -1.99999 0
  rotation 0 0 1 1.5708
  name "wall(3)"
  size 0.1 4 0.9
}
RobocupSoccerBall {
  translation 0.85 0.65 0.09
}
RubberDuck {
  translation -0.581023 -1.02224 0.71
  rotation 0 0 -1 -1.5708053071795867
}
Charger {
  translation 0.21 -1.95 0.08
  children [
    WallPlug {
      translation 1.46928e-07 -0.04 0.04
      rotation 0 0 1 1.5708
    }
  ]
}
DesktopComputer {
  translation 1.65 -0.78 0
  rotation 0 0 1 3.14159
}
FloorLight {
  translation 1.84 0.55 0
}
TrafficCone {
  translation 0.58 -0.16 0
  scale 0.5
}
TrafficCone {
  translation -0.68 0.94 0
  scale 0.5
  name "traffic cone(1)"
}
