#VRML_SIM R2025a utf8

EXTERNPROTO "https://raw.githubusercontent.com/cyberbotics/webots/R2025a/projects/objects/backgrounds/protos/TexturedBackground.proto"
EXTERNPROTO "https://raw.githubusercontent.com/cyberbotics/webots/R2025a/projects/objects/backgrounds/protos/TexturedBackgroundLight.proto"
EXTERNPROTO "https://raw.githubusercontent.com/cyberbotics/webots/R2025a/projects/objects/floors/protos/Floor.proto"
EXTERNPROTO "https://raw.githubusercontent.com/cyberbotics/webots/R2025a/projects/objects/factory/containers/protos/WoodenBox.proto"

WorldInfo {
  basicTimeStep 16
}
Viewpoint {
  orientation 0.19231571917016801 0.4903715365294671 -0.8500296584953908 0.8645484691587896
  position -1.1254061797184731 1.09039788029488 0.8680160058409966
}
TexturedBackground {
}
TexturedBackgroundLight {
}
Floor {
  size 1 1
}
DEF WALL_1 Solid {
  translation 0.5 0 0.05
  children [
    DEF WALL_SHAPE Shape {
      appearance PBRAppearance {
        baseColor 0.12549 0.368627 0.729412
        roughness 1
        metalness 0
      }
      geometry Box {
        size 0.02 0.98 0.1
      }
    }
  ]
  name "wall 1"
  boundingObject USE WALL_SHAPE
}
DEF WALL_2 Solid {
  translation -0.5 0 0.05
  children [
    USE WALL_SHAPE
  ]
  name "wall 2"
  boundingObject USE WALL_SHAPE
}
DEF WALL_3 Solid {
  translation 0 -0.5 0.05
  rotation 0 0 1 1.5708
  children [
    USE WALL_SHAPE
  ]
  name "wall 3"
  boundingObject USE WALL_SHAPE
}
DEF WALL_4 Solid {
  translation 0 0.5 0.05
  rotation 0 0 1 1.5708
  children [
    USE WALL_SHAPE
  ]
  name "wall 4"
  boundingObject USE WALL_SHAPE
}
Robot {
  translation 0.184222 0.0692083 0.0398605
  rotation -1.19636e-08 3.74648e-08 1 -3.046935307179586
  name "my_robot"
  children [
    DEF BODY Shape {
      appearance PBRAppearance {
        baseColor 0.6 0 0.9
        roughness 1
        metalness 0
      }
      geometry Box {
        size 0.2 0.1 0.05
      }
    }
    DEF WHEEL1 HingeJoint {
      jointParameters HingeJointParameters {
        position 2.5267556987634032
        axis 0 1 0
        anchor 0.05 0.06 0
      }
      device [
        RotationalMotor {
          name "wheel1"
        }
      ]
      endPoint Solid {
        translation 0.05 0.06 0
        rotation 0.21904327369469292 0.6899335284229295 -0.6899360626949417 2.7103190620757545
        children [
          DEF WHEEL Shape {
            appearance DEF WHEELCOLOR PBRAppearance {
              baseColor 1 0 0.25
              roughness 1
              metalness 0
            }
            geometry Cylinder {
              height 0.02
              radius 0.04
              subdivision 24
            }
          }
        ]
        boundingObject USE WHEEL
        physics Physics {
        }
      }
    }
    DEF WHEEL2 HingeJoint {
      jointParameters HingeJointParameters {
        position 2.52676
        axis 0 1 0
        anchor 0.05 -0.06 0
      }
      device [
        RotationalMotor {
          name "wheel2"
        }
      ]
      endPoint Solid {
        translation 0.05 -0.06 0
        rotation 0.2190417187141864 0.6899337752622885 -0.689936309535207 2.710322029643627
        children [
          USE WHEEL
        ]
        name "solid(1)"
        boundingObject USE WHEEL
        physics Physics {
        }
      }
    }
    DEF WHEEL3 HingeJoint {
      jointParameters HingeJointParameters {
        position 2.5267567110032805
        axis 0 1 0
        anchor -0.05 0.06 0
      }
      device [
        RotationalMotor {
          name "wheel3"
        }
      ]
      endPoint Solid {
        translation -0.05 0.06 0
        rotation 0.21904290775029156 0.6899335865135221 -0.6899361207857475 2.7103197604540137
        children [
          USE WHEEL
        ]
        name "solid(2)"
        boundingObject USE WHEEL
        physics Physics {
        }
      }
    }
    DEF WHEEL4 HingeJoint {
      jointParameters HingeJointParameters {
        position 2.5267568202372845
        axis 0 1 0
        anchor -0.05 -0.06 0
      }
      device [
        RotationalMotor {
          name "wheel4"
        }
      ]
      endPoint Solid {
        translation -0.05 -0.06 0
        rotation 0.2190428682600761 0.6899335927822553 -0.6899361270545036 2.7103198358182223
        children [
          USE WHEEL
        ]
        name "solid(3)"
        boundingObject USE WHEEL
        physics Physics {
        }
      }
    }
    DEF DS_RIGHT DistanceSensor {
      translation 0.1 -0.03 0
      rotation 0 0 1 -0.3
      children [
        Shape {
          appearance DEF SENSOR PBRAppearance {
            baseColor 0 0 1
            roughness 1
            metalness 0
          }
          geometry Box {
            size 0.01 0.01 0.01
          }
        }
      ]
      name "ds_right"
    }
    DEF DS_LEFT DistanceSensor {
      translation 0.1 0.03 0
      rotation 0 0 1 0.3
      children [
        Shape {
          appearance USE SENSOR
          geometry Box {
            size 0.01 0.01 0.01
          }
        }
      ]
      name "ds_left"
    }
  ]
  boundingObject USE BODY
  physics Physics {
    density -1
    mass 1
  }
  controller "<extern>"
}
WoodenBox {
  translation -0.251173 -8.55367e-05 0.0499608
  rotation -4.6329540143643653e-17 6.045105346690871e-17 0.9999999999999999 0.7853979999999999
  size 0.1 0.1 0.1
  mass 0.2
}
WoodenBox {
  translation 0.236729 -0.261714 0.0499608
  rotation 2.0625e-16 -8.5573e-17 1 -0.261795307179586
  name "wooden box(1)"
  size 0.1 0.1 0.1
  mass 0.2
}
